try{
    console.log((a+b));
}
catch(arr){
    console.log("There was an erro");
    console.log("The error was saved in teh error log");
}
console.log("There program does not stop")